<?xml version='1.0' encoding='utf-8'?>
<mujoco model="hand">
    <compiler angle="radian" />
    <option integrator="implicitfast" />
    <default>
        <geom solref="0.001 1" solimp="0.99 0.999 0.0001"/>
        <default class="cube">
            <geom friction="2.0 0.1 0.002" contype="2" conaffinity="1" condim="4" />
        </default>
        <default class="hand">
            <geom contype="1" conaffinity="2" type="mesh" density="1250" friction="0.7 0.05 0.0002" solref="0.02 1.5" solimp="0.9 0.95 0.001" condim="3" rgba="0 0 1 0"/>
        </default>
        <default class="visual">
            <geom contype="0" conaffinity="0" group="2" density="1"/>
        </default>
        <default class="tip">
            <geom type="sphere" size="0.0075" rgba="1 1 .6 .3" contype="1" conaffinity="2" density="1000" friction="12 0.2 0.01" solref="0.01 1" solimp="0.98 0.995 0.001" condim="6"/>
        </default>
        <!-- collision -->
        <default class="collision">
            <geom contype="1" conaffinity="2" density="1250" friction="1.0 0.1 0.001" solref="0.01 1" solimp="0.99 0.999 0.0001" condim="3" rgba="0.7 0.3 0.3 0.3"/>
        </default>
        <default class="palm_collision">
            <geom contype="1" conaffinity="2" density="1500" friction="1.0 0.1 0.001" solref="0.01 1" solimp="0.99 0.999 0.0001" condim="3" rgba="0.3 0.3 0.7 0.3"/>
        </default>
        <!-- tendon -->
        <default class="tendon">
            <tendon width=".0005" rgba="0 0 .9 1" solreflimit=".001 1" solimplimit="0.99 0.999 0.00001 0.1 20" stiffness="1"/>
        </default>
        <!-- joints -->
        <default class="thumb_joint">
            <joint type="hinge" solreflimit=".001 1" solimplimit="0.97 0.99 0.00001 0.1 2" damping="1" stiffness="1"/>
        </default>
        <default class="swing_joint">
            <joint type="hinge" solreflimit=".001 1" solimplimit="0.97 0.99 0.00001 0.1 2" damping="1" stiffness="1"/>
        </default>
        <default class="finger_joint">
            <joint type="hinge" range="0 1.57" limited="true" solreflimit=".001 1" solimplimit="0.97 0.99 0.00001 0.1 2" damping="1" stiffness="2"/>
        </default>
        <default class="palm_slide">
            <joint solreflimit=".001 1" solimplimit="0.97 0.99 0.00001 0.1 2" damping="1" stiffness="100"/>
        </default>
        <default class="palm_rotate">
            <joint solreflimit=".001 1" solimplimit="0.97 0.99 0.00001 0.1 2" damping="1" stiffness="60" limited="true"/>
        </default>
        <default class="touch_sensor">
            <site size="0.008" rgba="1 0 0 1" type="sphere"/>
        </default>
    </default>
    <asset>
        <texture type="2d" name="groundplane" builtin="checker" mark="edge" rgb1="1 1 1" rgb2="0 0 0" markrgb="0 0 0" width="300" height="300"/>
        <material name="groundplane" texture="groundplane" texuniform="true" texrepeat="5 5" reflectance="0"/>
        <mesh file="./meshes/palm.STL" name="mesh_0" />
        <mesh file="./meshes/thumb_link_0.STL" name="mesh_1" />
        <mesh file="./meshes/thumb_link_1.STL" name="mesh_2" />
        <mesh file="./meshes/thumb_link_2.STL" name="mesh_3" />
        <mesh file="./meshes/thumb_link_3.STL" name="mesh_4" />
        <mesh file="./meshes/index_link_0.STL" name="mesh_5" />
        <mesh file="./meshes/index_link_1.STL" name="mesh_6" />
        <mesh file="./meshes/index_link_2.STL" name="mesh_7" />
        <mesh file="./meshes/index_link_3.STL" name="mesh_8" />
        <mesh file="./meshes/middle_link_0.STL" name="mesh_9" />
        <mesh file="./meshes/middle_link_1.STL" name="mesh_10" />
        <mesh file="./meshes/middle_link_2.STL" name="mesh_11" />
        <mesh file="./meshes/middle_link_3.STL" name="mesh_12" />
        <mesh file="./meshes/ring_link_0.STL" name="mesh_13" />
        <mesh file="./meshes/ring_link_1.STL" name="mesh_14" />
        <mesh file="./meshes/ring_link_2.STL" name="mesh_15" />
        <mesh file="./meshes/ring_link_3.STL" name="mesh_16" />
        <mesh file="./meshes/little_link_0.STL" name="mesh_17" />
        <mesh file="./meshes/little_link_1.STL" name="mesh_18" />
        <mesh file="./meshes/little_link_2.STL" name="mesh_19" />
        <mesh file="./meshes/little_link_3.STL" name="mesh_20" />
    </asset>
    <option gravity="0 0 -9.81"/>
    <keyframe>
        <key name="home" qpos="0 0 0 0 0 0 0 0 0 0 0 0 0 0 0 0 0 0 0 0 0 0 0 0 0 0 0 0 0 0 0 0" qvel="0 0 0 0 0 0 0 0 0 0 0 0 0 0 0 0 0 0 0 0 0 0 0 0 0 0 0 0 0 0 0" ctrl="0 0 0 0 0 0 0 0 0 0 0 0 0 0 0 0 0 0 0 0 0 0" />
    </keyframe>
    <worldbody>
        <geom name="floor" pos="0 0 0" size="0 0 0.01" type="plane" material="groundplane" contype="1" conaffinity="2" friction="1 0.05 0.05" solref="0.001 1" solimp="0.98 0.99 0.001"/>
        <site name="target" pos="0 0 0.3" size="0.002" rgba="1 0 0 1"/>
        <body name="palm" pos="0 0 0.5" euler="3.14 1.57 -1.57" childclass="hand">
            <!-- inner site -->
            <site name="inner_palm_1" pos="-0.02 -0.02 0.02" size="0.001" rgba="0 1 0 1"/>
            <site name="inner_palm_2" pos="0.05 -0.02 0.02" size="0.001" rgba="0 1 0 1"/>
            <site name="inner_palm_3" pos="-0.02 -0.02 0.09" size="0.001" rgba="0 1 0 1"/>
            <site name="inner_palm_4" pos="0.05 -0.02 0.09" size="0.001" rgba="0 1 0 1"/>
            <site name="inner_palm_5" pos="0.015 -0.02 0.055" size="0.002" rgba="0 0 1 1"/>
            <!-- outer site -->
            <site name="outer_palm_1" pos="-0.02 0.02 0.02" size="0.001" rgba="0.6 0 0 1"/>
            <site name="outer_palm_2" pos="0.05 0.02 0.02" size="0.001" rgba="0.6 0 0 1"/>
            <site name="outer_palm_3" pos="-0.02 0.02 0.09" size="0.001" rgba="0.6 0 0 1"/>
            <site name="outer_palm_4" pos="0.05 0.02 0.09" size="0.001" rgba="0.6 0 0 1"/>
            <site name="outer_palm_5" pos="0.015 0.02 0.055" size="0.001" rgba="0.6 0 0 1"/>
            <!-- tendon site -->
            <site name="index_t0" pos="0.059512 -0.015 0.082" size="0.002" rgba="0 0.6 0 1"/>
            <site name="middle_t0" pos="0.031512 -0.015 0.082" size="0.002" rgba="0 0.6 0 1"/>
            <site name="ring_t0" pos="0.003512 -0.015 0.082" size="0.002" rgba="0 0.6 0 1"/>
            <site name="little_t0" pos="-0.024488 -0.015 0.082" size="0.002" rgba="0 0.6 0 1"/>
            <joint name="palm_slide_x" type="slide" axis="1 0 0" class="palm_slide"/>
            <joint name="palm_slide_y" type="slide" axis="0 0 1" class="palm_slide"/>
            <joint name="palm_slide_z" type="slide" axis="0 1 0" class="palm_slide"/>
            <joint name="palm_rotate_x" type="hinge" axis="1 0 0" range="-1.57 1.57" class="palm_rotate"/>
            <joint name="palm_rotate_y" type="hinge" axis="0 1 0" range="-1.57 1.57" class="palm_rotate"/>
            <joint name="palm_rotate_z" type="hinge" axis="0 0 1" range="-3.14 3.14" class="palm_rotate"/>
            <geom name="palm_collision_1" type="box" pos="0.02 0 0.05" size="0.06 0.02 0.07" class="palm_collision"/>
            <geom name="palm_collision_2" type="box" pos="0.018 0 -0.07" size="0.032 0.02 0.05" class="palm_collision"/>
            <geom type="mesh" mesh="mesh_0" pos="0 0 0" class="visual"/>
            <body name="thumb_link_0" pos="0.029812 0 -0.017086" euler="3.14 1.57 0">
                <joint name="thumb_joint_0" type="hinge" axis="0 1 0" class="thumb_joint"/>
                <geom type="mesh" mesh="mesh_1" pos="0 0 0" class="visual"/>
                <body name="thumb_link_1" pos="0 0.011600 0.008500" euler="-0.57 0 0">
                    <joint name="thumb_joint_1" type="hinge" axis="-1 0 0" class="thumb_joint"/>
                    <geom type="mesh" mesh="mesh_2" pos="0 0 0" class="visual"/>
                    <geom name="thumb_link_1_collision" type="capsule" fromto="0 0 0 0 0 0.03" size="0.012" class="collision"/>
                    <body name="thumb_link_2" pos="0 0 0.033000" euler="-1.57 0 -1.57">
                        <!-- inner site -->
                        <site name="inner_thumb_2_1" pos="0.005 0.008 0.008" size="0.001" rgba="0 1 0 1"/>
                        <site name="inner_thumb_2_2" pos="0.005 0.008 -0.008" size="0.001" rgba="0 1 0 1"/>
                        <site name="inner_thumb_2_3" pos="0.04 0.008 0.008" size="0.001" rgba="0 1 0 1"/>
                        <site name="inner_thumb_2_4" pos="0.04 0.008 -0.008" size="0.001" rgba="0 1 0 1"/>
                        <!-- thumb site -->
                        <site name="outer_thumb_2_1" pos="0.005 -0.004 0.008" size="0.001" rgba="0.6 0 0 1"/>
                        <site name="outer_thumb_2_2" pos="0.005 -0.004 -0.008" size="0.001" rgba="0.6 0 0 1"/>
                        <site name="outer_thumb_2_3" pos="0.04 -0.004 0.008" size="0.001" rgba="0.6 0 0 1"/>
                        <site name="outer_thumb_2_4" pos="0.04 -0.004 -0.008" size="0.001" rgba="0.6 0 0 1"/>
                        <!-- joint -->
                        <joint name="thumb_joint_2" type="hinge" axis="0 0 1" class="thumb_joint" />
                        <geom type="mesh" mesh="mesh_3" pos="0 0 0" class="visual"/>
                        <geom name="thumb_link_2_collision" type="capsule" fromto="0.005 0.002 0 0.04 0.002 0" size="0.011" class="collision"/>
                        <body name="thumb_link_3" pos="0.045220 0 0" euler="0 0 -3.14">
                            <!-- inner site -->
                            <site name="inner_thumb_3_1" pos="-0.009 -0.007 0.0085" size="0.001" rgba="0 1 0 1"/>
                            <site name="inner_thumb_3_2" pos="-0.009 -0.007 -0.008" size="0.001" rgba="0 1 0 1"/>
                            <site name="inner_thumb_3_3" pos="-0.041 -0.007 0.0085" size="0.001" rgba="0 1 0 1"/>
                            <site name="inner_thumb_3_4" pos="-0.041 -0.007 -0.008" size="0.001" rgba="0 1 0 1"/>
                            <!-- outer site -->
                            <site name="outer_thumb_3_1" pos="-0.009 0.002 0.0085" size="0.001" rgba="0.6 0 0 1"/>
                            <site name="outer_thumb_3_2" pos="-0.009 0.002 -0.008" size="0.001" rgba="0.6 0 0 1"/>
                            <site name="outer_thumb_3_3" pos="-0.041 0.002 0.0085" size="0.001" rgba="0.6 0 0 1"/>
                            <site name="outer_thumb_3_4" pos="-0.041 0.002 -0.008" size="0.001" rgba="0.6 0 0 1"/>
                            <!-- joint -->
                            <joint name="thumb_joint_3" type="hinge" axis="0 0 1" class="thumb_joint"/>
                            <geom type="mesh" mesh="mesh_4" pos="0 0 0" class="visual"/>
                            <geom name="thumb_link_3_collision" type="capsule" fromto="-0.01 -0.004 0 -0.05 -0.004 0" size="0.01" class="collision"/>
                            <site name="thumb_tip" pos="-0.05 -0.004 0" class="touch_sensor" size="0.0105"/>
                        </body>
                    </body>
                </body>
            </body>
            <body name="index_link_0" pos="0.059512 0 0.099564" euler="1.57 0 3.14">
                <joint name="index_swing" axis="0 0 1." class="swing_joint"/>
                <geom type="mesh" mesh="mesh_5" pos="0 0 0" class="visual"/>
                <!-- <site name="index_t0" pos="0 0.035 0.02" size="0.0032" rgba="1 0 0 1"/> -->
                <site name="index_t12" pos="0 0 0.02" size="0.001" rgba="1 0 0 1"/>
                <body name="index_link_1" pos="0 -0.012000 0.018000" euler="1.57 -1.57 0">
                    <!-- inner site -->
                    <site name="inner_index_1_1" pos="0.006 0.0075 0.008" size="0.001" rgba="0 1 0 1"/>
                    <site name="inner_index_1_2" pos="0.006 0.0075 -0.008" size="0.001" rgba="0 1 0 1"/>
                    <site name="inner_index_1_3" pos="0.05 0.0075 0.008" size="0.001" rgba="0 1 0 1"/>
                    <site name="inner_index_1_4" pos="0.05 0.0075 -0.008" size="0.001" rgba="0 1 0 1"/>
                    <!-- outer site -->
                    <site name="outer_index_1_1" pos="0.006 -0.001 0.008" size="0.001" rgba="0.6 0 0 1"/>
                    <site name="outer_index_1_2" pos="0.006 -0.001 -0.008" size="0.001" rgba="0.6 0 0 1"/>
                    <site name="outer_index_1_3" pos="0.05 -0.001 0.008" size="0.001" rgba="0.6 0 0 1"/>
                    <site name="outer_index_1_4" pos="0.05 -0.001 -0.008" size="0.001" rgba="0.6 0 0 1"/>
                    <!-- joint -->
                    <joint name="index_joint_0" axis="0 0 1" class="finger_joint"/>
                    <geom name="index_link_1_collision" type="capsule" fromto="0 0.0045 0 0.045 0.0045 0" size="0.01" class="collision"/>
                    <geom type="mesh" mesh="mesh_6" pos="0 0 0" class="visual"/>
                    <body name="index_link_2" pos="0.056000 0 0" euler="-3.14 0 -3.14">
                        <!-- inner site -->
                        <site name="inner_index_2_1" pos="-0.006 0.007 -0.0075" size="0.001" rgba="0 1 0 1"/>
                        <site name="inner_index_2_2" pos="-0.006 0.007 0.0075" size="0.001" rgba="0 1 0 1"/>
                        <site name="inner_index_2_3" pos="-0.029 0.007 -0.0075" size="0.001" rgba="0 1 0 1"/>
                        <site name="inner_index_2_4" pos="-0.029 0.007 0.0075" size="0.001" rgba="0 1 0 1"/>
                        <!-- outer site -->
                        <site name="outer_index_2_1" pos="-0.006 -0.0005 -0.0075" size="0.001" rgba="0.6 0 0 1"/>
                        <site name="outer_index_2_2" pos="-0.006 -0.0005 0.0075" size="0.001" rgba="0.6 0 0 1"/>
                        <site name="outer_index_2_3" pos="-0.029 -0.0005 -0.0075" size="0.001" rgba="0.6 0 0 1"/>
                        <site name="outer_index_2_4" pos="-0.029 -0.0005 0.0075" size="0.001" rgba="0.6 0 0 1"/>
                        <!-- joint -->
                        <joint name="index_joint_1" axis="0 0 -1" class="finger_joint"/>
                        <geom name="index_link_2_collision" type="box" pos="-0.018 0.004 0" size="0.016 0.004 0.008" class="collision"/>
                        <site name="index_t1_2_1" pos="-0.004 0.005 -0.005" size="0.001" rgba="1 0 0 1"/>
                        <site name="index_t2_2_1" pos="-0.004 0.005 0.005" size="0.001" rgba="1 0 0 1"/>
                        <site name="index_t1_2_2" pos="-0.031 0.005 -0.005" size="0.001" rgba="1 0 0 1"/>
                        <site name="index_t2_2_2" pos="-0.031 0.005 0.005" size="0.001" rgba="1 0 0 1"/>
                        <geom type="mesh" mesh="mesh_7" pos="0 0 0" class="visual"/>
                        <body name="index_link_3" pos="-0.035000 0 -0.006128" euler="-3.14 0 3.14">
                            <!-- inner site -->
                            <site name="inner_index_3_1" pos="0.006 0.007 0.0016" size="0.001" rgba="0 1 0 1"/>
                            <site name="inner_index_3_2" pos="0.006 0.007 -0.014" size="0.001" rgba="0 1 0 1"/>
                            <site name="inner_index_3_3" pos="0.029 0.007 0.0016" size="0.001" rgba="0 1 0 1"/>
                            <site name="inner_index_3_4" pos="0.029 0.007 -0.014" size="0.001" rgba="0 1 0 1"/>
                            <!-- outer site -->
                            <site name="outer_index_3_1" pos="0.006 -0.0005 0.0016" size="0.001" rgba="0.6 0 0 1"/>
                            <site name="outer_index_3_2" pos="0.006 -0.0005 -0.014" size="0.001" rgba="0.6 0 0 1"/>
                            <site name="outer_index_3_3" pos="0.029 -0.0005 0.0016" size="0.001" rgba="0.6 0 0 1"/>
                            <site name="outer_index_3_4" pos="0.029 -0.0005 -0.014" size="0.001" rgba="0.6 0 0 1"/>
                            <!-- joint -->
                            <joint name="index_joint_2" axis="0 0 1" class="finger_joint"/>
                            <site name="index_t1_3_1" pos="0.004 0.005 -0.001" size="0.001" rgba="1 0 0 1"/>
                            <site name="index_t2_3_1" pos="0.004 0.005 -0.011" size="0.001" rgba="1 0 0 1"/>
                            <geom type="mesh" mesh="mesh_8" pos="0 0 0" class="visual"/>
                            <geom name="index_link_3_collision" type="box" pos="0.018 0.004 -0.006" size="0.016 0.004 0.008" class="collision"/>
                            <geom name="index_tip" type="sphere" pos="0.03 0.004 -0.006" size="0.008" class="tip"/>
                            <site name="index_tip" pos="0.03 0.004 -0.006" class="touch_sensor"/>
                        </body>
                    </body>
                </body>
            </body>
            <body name="middle_link_0" pos="0.031512 0 0.099564" euler="1.57 0 3.14">
                <joint name="middle_swing" axis="0 0 1" class="swing_joint"/>
                <geom type="mesh" mesh="mesh_9" pos="0 0 0" class="visual"/>
                <!-- <site name="middle_t0" pos="0 0.035 0.02" size="0.0032" rgba="1 0 0 1"/> -->
                <site name="middle_t12" pos="0 0 0.02" size="0.001" rgba="1 0 0 1"/>
                <body name="middle_link_1" pos="0 -0.012000 0.018000" euler="1.57 -1.57 0">
                    <!-- inner site -->
                    <site name="inner_middle_1_1" pos="0.006 0.007 -0.0075" size="0.001" rgba="0 1 0 1"/>
                    <site name="inner_middle_1_2" pos="0.006 0.007 0.0075" size="0.001" rgba="0 1 0 1"/>
                    <site name="inner_middle_1_3" pos="0.06 0.007 -0.0075" size="0.001" rgba="0 1 0 1"/>
                    <site name="inner_middle_1_4" pos="0.06 0.007 0.0075" size="0.001" rgba="0 1 0 1"/>
                    <!-- outer site -->
                    <site name="outer_middle_1_1" pos="0.006 -0.001 -0.0075" size="0.001" rgba="0.6 0 0 1"/>
                    <site name="outer_middle_1_2" pos="0.006 -0.001 0.0075" size="0.001" rgba="0.6 0 0 1"/>
                    <site name="outer_middle_1_3" pos="0.06 -0.001 -0.0075" size="0.001" rgba="0.6 0 0 1"/>
                    <site name="outer_middle_1_4" pos="0.06 -0.001 0.0075" size="0.001" rgba="0.6 0 0 1"/>
                    <!-- joint -->
                    <joint name="middle_joint_0" axis="0 0 1" class="finger_joint"/>
                    <geom type="mesh" mesh="mesh_10" pos="0 0 0" class="visual"/>
                    <geom name="middle_link_1_collision" type="capsule" fromto="0 0.0045 0 0.055 0.0045 0" size="0.01" class="collision"/>
                    <body name="middle_link_2" pos="0.066000 0 0" euler="0 0 0">
                        <!-- inner site -->
                        <site name="inner_middle_2_1" pos="0.006 0.007 0.0075" size="0.001" rgba="0 1 0 1"/>
                        <site name="inner_middle_2_2" pos="0.006 0.007 -0.0075" size="0.001" rgba="0 1 0 1"/>
                        <site name="inner_middle_2_3" pos="0.034 0.007 0.0075" size="0.001" rgba="0 1 0 1"/>
                        <site name="inner_middle_2_4" pos="0.034 0.007 -0.0075" size="0.001" rgba="0 1 0 1"/>
                        <!-- outer site -->
                        <site name="outer_middle_2_1" pos="0.006 -0.0005 0.0075" size="0.001" rgba="0.6 0 0 1"/>
                        <site name="outer_middle_2_2" pos="0.006 -0.0005 -0.0075" size="0.001" rgba="0.6 0 0 1"/>
                        <site name="outer_middle_2_3" pos="0.034 -0.0005 0.0075" size="0.001" rgba="0.6 0 0 1"/>
                        <site name="outer_middle_2_4" pos="0.034 -0.0005 -0.0075" size="0.001" rgba="0.6 0 0 1"/>
                        <!-- joint -->
                        <joint name="middle_joint_1" axis="0 0 1" class="finger_joint"/>
                        <site name="middle_t1_2_1" pos="0.004 0.005 0.005" size="0.001" rgba="1 0 0 1"/>
                        <site name="middle_t2_2_1" pos="0.004 0.005 -0.005" size="0.001" rgba="1 0 0 1"/>
                        <site name="middle_t1_2_2" pos="0.036 0.005 0.005" size="0.001" rgba="1 0 0 1"/>
                        <site name="middle_t2_2_2" pos="0.036 0.005 -0.005" size="0.001" rgba="1 0 0 1"/>
                        <geom type="mesh" mesh="mesh_11" pos="0 0 0" class="visual"/>
                        <geom name="middle_link_2_collision" type="box" pos="0.020 0.004 0" size="0.018 0.004 0.008" class="collision"/>
                        <body name="middle_link_3" pos="0.040000 0 0" euler="0 0 0">
                            <!-- inner site -->
                            <site name="inner_middle_3_1" pos="0.006 0.007 0.0075" size="0.001" rgba="0 1 0 1"/>
                            <site name="inner_middle_3_2" pos="0.006 0.007 -0.0075" size="0.001" rgba="0 1 0 1"/>
                            <site name="inner_middle_3_3" pos="0.03 0.007 0.0075" size="0.001" rgba="0 1 0 1"/>
                            <site name="inner_middle_3_4" pos="0.03 0.007 -0.0075" size="0.001" rgba="0 1 0 1"/>
                            <!-- outer site -->
                            <site name="outer_middle_3_1" pos="0.006 -0.0005 0.0075" size="0.001" rgba="0.6 0 0 1"/>
                            <site name="outer_middle_3_2" pos="0.006 -0.0005 -0.0075" size="0.001" rgba="0.6 0 0 1"/>
                            <site name="outer_middle_3_3" pos="0.03 -0.0005 0.0075" size="0.001" rgba="0.6 0 0 1"/>
                            <site name="outer_middle_3_4" pos="0.03 -0.0005 -0.0075" size="0.001" rgba="0.6 0 0 1"/>
                            <!-- joint -->
                            <joint name="middle_joint_2" axis="0 0 1" class="finger_joint"/>
                            <site name="middle_t1_3_1" pos="0.004 0.005 0.005" size="0.001" rgba="1 0 0 1"/>
                            <site name="middle_t2_3_1" pos="0.004 0.005 -0.005" size="0.001" rgba="1 0 0 1"/>
                            <geom type="mesh" mesh="mesh_12" pos="0 0 0" class="visual"/>
                            <geom name="middle_link_3_collision" type="box" pos="0.019 0.004 0" size="0.015 0.004 0.008" class="collision"/>
                            <geom name="middle_tip" type="sphere" pos="0.03 0.004 0" size="0.008" class="tip"/>
                            <site name="middle_tip" pos="0.03 0.004 0" class="touch_sensor"/>
                        </body>
                    </body>
                </body>
            </body>
            <body name="ring_link_0" pos="0.003512 0 0.099564" euler="1.57 0 3.14">
                <joint name="ring_swing" axis="0 0 1" class="swing_joint"/>
                <!-- <site name="ring_t0" pos="0 0.035 0.02" size="0.0032" rgba="1 0 0 1"/> -->
                <site name="ring_t12" pos="0 0 0.02" size="0.001" rgba="1 0 0 1"/>
                <geom type="mesh" mesh="mesh_13" pos="0 0 0" class="visual"/>
                <body name="ring_link_1" pos="0 -0.012000 0.018000" euler="1.57 -1.57 0">
                    <!-- inner site -->
                    <site name="inner_ring_1_1" pos="0.006 0.0075 0.008" size="0.001" rgba="0 1 0 1"/>
                    <site name="inner_ring_1_2" pos="0.006 0.0075 -0.008" size="0.001" rgba="0 1 0 1"/>
                    <site name="inner_ring_1_3" pos="0.054 0.0075 0.008" size="0.001" rgba="0 1 0 1"/>
                    <site name="inner_ring_1_4" pos="0.054 0.0075 -0.008" size="0.001" rgba="0 1 0 1"/>
                    <!-- outer site -->
                    <site name="outer_ring_1_1" pos="0.006 -0.001 0.008" size="0.001" rgba="0.6 0 0 1"/>
                    <site name="outer_ring_1_2" pos="0.006 -0.001 -0.008" size="0.001" rgba="0.6 0 0 1"/>
                    <site name="outer_ring_1_3" pos="0.054 -0.001 0.008" size="0.001" rgba="0.6 0 0 1"/>
                    <site name="outer_ring_1_4" pos="0.054 -0.001 -0.008" size="0.001" rgba="0.6 0 0 1"/>
                    <!-- joint -->
                    <joint name="ring_joint_0" axis="0 0 1" class="finger_joint"/>
                    <geom type="mesh" mesh="mesh_14" pos="0 0 0" class="visual"/>
                    <geom name="ring_link_1_collision" type="capsule" fromto="0 0.0045 0 0.050 0.0045 0" size="0.01" class="collision"/>
                    <body name="ring_link_2" pos="0.060000 0 0.011414" euler="3.14 0 -3.14">
                        <!-- inner site -->
                        <site name="inner_ring_2_1" pos="-0.006 0.007 0.0035" size="0.001" rgba="0 1 0 1"/>
                        <site name="inner_ring_2_2" pos="-0.006 0.007 0.019" size="0.001" rgba="0 1 0 1"/>
                        <site name="inner_ring_2_3" pos="-0.031 0.007 0.0035" size="0.001" rgba="0 1 0 1"/>
                        <site name="inner_ring_2_4" pos="-0.031 0.007 0.019" size="0.001" rgba="0 1 0 1"/>
                        <!-- outer site -->
                        <site name="outer_ring_2_1" pos="-0.006 -0.0005 0.0035" size="0.001" rgba="0.6 0 0 1"/>
                        <site name="outer_ring_2_2" pos="-0.006 -0.0005 0.019" size="0.001" rgba="0.6 0 0 1"/>
                        <site name="outer_ring_2_3" pos="-0.031 -0.0005 0.0035" size="0.001" rgba="0.6 0 0 1"/>
                        <site name="outer_ring_2_4" pos="-0.031 -0.0005 0.019" size="0.001" rgba="0.6 0 0 1"/>
                        <!-- joint -->
                        <joint name="ring_joint_1" axis="0 0 -1" class="finger_joint"/>
                        <geom type="mesh" mesh="mesh_15" pos="0 0 0" class="visual"/>
                        <site name="ring_t1_2_1" pos="-0.004 0.005 0.0165" size="0.001" rgba="1 0 0 1"/>
                        <site name="ring_t2_2_1" pos="-0.004 0.005 0.0065" size="0.001" rgba="1 0 0 1"/>
                        <site name="ring_t1_2_2" pos="-0.033 0.005 0.0165" size="0.001" rgba="1 0 0 1"/>
                        <site name="ring_t2_2_2" pos="-0.033 0.005 0.0065" size="0.001" rgba="1 0 0 1"/>
                        <geom name="ring_link_2_collision" type="box" pos="-0.018 0.004 0.011" size="0.018 0.004 0.008" class="collision"/>
                        <body name="ring_link_3" pos="-0.037000 0 0.000235" euler="3.14 0 -3.14">
                            <!-- inner site -->
                            <site name="inner_ring_3_1" pos="0.006 0.007 -0.0035" size="0.001" rgba="0 1 0 1"/>
                            <site name="inner_ring_3_2" pos="0.006 0.007 -0.019" size="0.001" rgba="0 1 0 1"/>
                            <site name="inner_ring_3_3" pos="0.029 0.007 -0.0035" size="0.001" rgba="0 1 0 1"/>
                            <site name="inner_ring_3_4" pos="0.029 0.007 -0.019" size="0.001" rgba="0 1 0 1"/>
                            <!-- outer site -->
                            <site name="outer_ring_3_1" pos="0.006 -0.0005 -0.0035" size="0.001" rgba="0.6 0 0 1"/>
                            <site name="outer_ring_3_2" pos="0.006 -0.0005 -0.019" size="0.001" rgba="0.6 0 0 1"/>
                            <site name="outer_ring_3_3" pos="0.029 -0.0005 -0.0035" size="0.001" rgba="0.6 0 0 1"/>
                            <site name="outer_ring_3_4" pos="0.029 -0.0005 -0.019" size="0.001" rgba="0.6 0 0 1"/>
                            <!-- joint -->
                            <joint name="ring_joint_2" axis="0 0 1" class="finger_joint"/>
                            <site name="ring_t1_3_1" pos="0.004 0.005 -0.016" size="0.001" rgba="1 0 0 1"/>
                            <site name="ring_t2_3_1" pos="0.004 0.005 -0.006" size="0.001" rgba="1 0 0 1"/>
                            <geom type="mesh" mesh="mesh_16" pos="0 0 0" class="visual"/>
                            <geom name="ring_link_3_collision" type="box" pos="0.018 0.004 -0.011" size="0.015 0.004 0.008" class="collision"/>
                            <geom name="ring_tip" type="sphere" pos="0.03 0.004 -0.011" size="0.008" class="tip"/>
                            <site name="ring_tip" pos="0.03 0.004 -0.011" class="touch_sensor"/>
                        </body>
                    </body>
                </body>
            </body>
            <body name="little_link_0" pos="-0.024488 0 0.099564" euler="1.57 0 3.14">
                <joint name="little_swing" axis="0 0 1" class="swing_joint"/>
                <!-- <site name="little_t0" pos="0 0.035 0.02" size="0.0032" rgba="1 0 0 1"/> -->
                <site name="little_t12" pos="0 0 0.02" size="0.001" rgba="1 0 0 1"/>
                <geom type="mesh" mesh="mesh_17" pos="0 0 0" class="visual"/>
                <body name="little_link_1" pos="0 -0.012000 0.018000" euler="1.57 -1.57 0">
                    <!-- inner site -->
                    <site name="inner_little_1_1" pos="0.007 0.0075 0.008" size="0.001" rgba="0 1 0 1"/>
                    <site name="inner_little_1_2" pos="0.007 0.0075 -0.008" size="0.001" rgba="0 1 0 1"/>
                    <site name="inner_little_1_3" pos="0.044 0.0075 0.008" size="0.001" rgba="0 1 0 1"/>
                    <site name="inner_little_1_4" pos="0.044 0.0075 -0.008" size="0.001" rgba="0 1 0 1"/>
                    <!-- outer site -->
                    <site name="outer_little_1_1" pos="0.007 -0.001 0.008" size="0.001" rgba="0.6 0 0 1"/>
                    <site name="outer_little_1_2" pos="0.007 -0.001 -0.008" size="0.001" rgba="0.6 0 0 1"/>
                    <site name="outer_little_1_3" pos="0.044 -0.001 0.008" size="0.001" rgba="0.6 0 0 1"/>
                    <site name="outer_little_1_4" pos="0.044 -0.001 -0.008" size="0.001" rgba="0.6 0 0 1"/>
                    <!-- joint -->
                    <joint name="little_joint_0" axis="0 0 1" class="finger_joint"/>
                    <geom type="mesh" mesh="mesh_18" pos="0 0 0" class="visual"/>
                    <geom name="little_link_1_collision" type="capsule" fromto="0 0.0045 0 0.04 0.0045 0" size="0.01" class="collision"/>
                    <body name="little_link_2" pos="0.050000 0 -0.014092" euler="-3.14 0 3.14">
                        <!-- inner site -->
                        <site name="inner_little_2_1" pos="-0.006 0.007 -0.022" size="0.001" rgba="0 1 0 1"/>
                        <site name="inner_little_2_2" pos="-0.006 0.007 -0.0062" size="0.001" rgba="0 1 0 1"/>
                        <site name="inner_little_2_3" pos="-0.019 0.007 -0.022" size="0.001" rgba="0 1 0 1"/>
                        <site name="inner_little_2_4" pos="-0.019 0.007 -0.0062" size="0.001" rgba="0 1 0 1"/>
                        <!-- outer site -->
                        <site name="outer_little_2_1" pos="-0.006 -0.0005 -0.022" size="0.001" rgba="0.6 0 0 1"/>
                        <site name="outer_little_2_2" pos="-0.006 -0.0005 -0.0062" size="0.001" rgba="0.6 0 0 1"/>
                        <site name="outer_little_2_3" pos="-0.019 -0.0005 -0.022" size="0.001" rgba="0.6 0 0 1"/>
                        <site name="outer_little_2_4" pos="-0.019 -0.0005 -0.0062" size="0.001" rgba="0.6 0 0 1"/>
                        <!-- joint -->
                        <joint name="little_joint_1" axis="0 0 -1" class="finger_joint"/>
                        <site name="little_t1_2_1" pos="-0.004 0.005 -0.019" size="0.001" rgba="1 0 0 1"/>
                        <site name="little_t2_2_1" pos="-0.004 0.005 -0.009" size="0.001" rgba="1 0 0 1"/>
                        <site name="little_t1_2_2" pos="-0.021 0.005 -0.019" size="0.001" rgba="1 0 0 1"/>
                        <site name="little_t2_2_2" pos="-0.021 0.005 -0.009" size="0.001" rgba="1 0 0 1"/>
                        <geom type="mesh" mesh="mesh_19" pos="0 0 0" class="visual"/>
                        <geom name="little_link_2_collision" type="box" pos="-0.013 0.004 -0.014" size="0.01 0.004 0.008" class="collision"/>
                        <body name="little_link_3" pos="-0.025000 0 0.002130" euler="-3.14 0 -3.14">
                            <!-- inner site -->
                            <site name="inner_little_3_1" pos="0.006 0.007 0.024" size="0.001" rgba="0 1 0 1"/>
                            <site name="inner_little_3_2" pos="0.006 0.007 0.0082" size="0.001" rgba="0 1 0 1"/>
                            <site name="inner_little_3_3" pos="0.028 0.007 0.024" size="0.001" rgba="0 1 0 1"/>
                            <site name="inner_little_3_4" pos="0.028 0.007 0.0082" size="0.001" rgba="0 1 0 1"/>
                            <!-- outer site -->
                            <site name="outer_little_3_1" pos="0.006 -0.0005 0.024" size="0.001" rgba="0.6 0 0 1"/>
                            <site name="outer_little_3_2" pos="0.006 -0.0005 0.0082" size="0.001" rgba="0.6 0 0 1"/>
                            <site name="outer_little_3_3" pos="0.028 -0.0005 0.024" size="0.001" rgba="0.6 0 0 1"/>
                            <site name="outer_little_3_4" pos="0.028 -0.0005 0.0082" size="0.001" rgba="0.6 0 0 1"/>
                            <!-- joint -->
                            <joint name="little_joint_2" axis="0 0 1" class="finger_joint"/>
                            <site name="little_t1_3_1" pos="0.004 0.005 0.0213" size="0.001" rgba="1 0 0 1"/>
                            <site name="little_t2_3_1" pos="0.004 0.005 0.0113" size="0.001" rgba="1 0 0 1"/>
                            <geom type="mesh" mesh="mesh_20" pos="0 0 0" class="visual"/>
                            <geom name="little_link_3_collision" type="box" pos="0.016 0.004 0.016" size="0.012 0.004 0.008" class="collision"/>
                            <geom name="little_tip" type="sphere" pos="0.028 0.004 0.016" size="0.008" class="tip"/>
                            <site name="little_tip" pos="0.028 0.004 0.016" class="touch_sensor"/>
                        </body>
                    </body>
                </body>
            </body>
        </body>
        <!-- 待抓取方块 -->
        <body name="cube" pos="0.0 0.0 0.05" quat="0 0 0 1" childclass="cube">
            <freejoint name="cube_freejoint"/>
            <geom name="cube" type="box" size="0.05 0.05 0.05" rgba="0 1 0 1" density="500"/>
            <site name="cube_center" pos="0 0 0" group="4"/>
        </body>
    </worldbody>
    <tendon>
        <!-- index -->
        <spatial name="index_tendon" class="tendon">
            <site site="index_t0"/>
            <site site="index_t12"/>
            <pulley divisor="2"/>
            <site site="index_t12"/>
            <site site="index_t1_2_1"/>
            <site site="index_t1_2_2"/>
            <site site="index_t1_3_1"/>
            <pulley divisor="2"/>
            <site site="index_t12"/>
            <site site="index_t2_2_1"/>
            <site site="index_t2_2_2"/>
            <site site="index_t2_3_1"/>
        </spatial>
        <!-- middle -->
        <spatial name="middle_tendon" class="tendon">
            <site site="middle_t0"/>
            <site site="middle_t12"/>
            <pulley divisor="2"/>
            <site site="middle_t12"/>
            <site site="middle_t1_2_1"/>
            <site site="middle_t1_2_2"/>
            <site site="middle_t1_3_1"/>
            <pulley divisor="2"/>
            <site site="middle_t12"/>
            <site site="middle_t2_2_1"/>
            <site site="middle_t2_2_2"/>
            <site site="middle_t2_3_1"/>
        </spatial>
        <!-- ring -->
        <spatial name="ring_tendon" class="tendon">
            <site site="ring_t0"/>
            <site site="ring_t12"/>
            <pulley divisor="2"/>
            <site site="ring_t12"/>
            <site site="ring_t1_2_1"/>
            <site site="ring_t1_2_2"/>
            <site site="ring_t1_3_1"/>
            <pulley divisor="2"/>
            <site site="ring_t12"/>
            <site site="ring_t2_2_1"/>
            <site site="ring_t2_2_2"/>
            <site site="ring_t2_3_1"/>
        </spatial>
        <spatial name="little_tendon" class="tendon">
            <site site="little_t0"/>
            <site site="little_t12"/>
            <pulley divisor="2"/>
            <site site="little_t12"/>
            <site site="little_t1_2_1"/>
            <site site="little_t1_2_2"/>
            <site site="little_t1_3_1"/>
            <pulley divisor="2"/>
            <site site="little_t12"/>
            <site site="little_t2_2_1"/>
            <site site="little_t2_2_2"/>
            <site site="little_t2_3_1"/>
        </spatial>
    </tendon>
    <actuator>
        <!-- 驱动器对应action速查
            [0:3]对应thumb转动关节
            [4:7]对应四指swing关节
            [8:11]对应四指最靠近手掌的关节
            [12:15]对应四指绳驱动
            [16:21]对应palm平移旋转关节
        -->
        <!-- 直接驱动 -->
        <position name="thumb_joint_0" joint="thumb_joint_0" ctrllimited="true" ctrlrange="-1 1" kp="10"/>
        <position name="thumb_joint_1" joint="thumb_joint_1" ctrllimited="true" ctrlrange="-1 1" gear="0.5" kp="40"/>
        <position name="thumb_joint_2" joint="thumb_joint_2" ctrllimited="true" ctrlrange="-1 1" kp="10"/>
        <position name="thumb_joint_3" joint="thumb_joint_3" ctrllimited="true" ctrlrange="-1 1" kp="10"/>
        <position name="index_swing" joint="index_swing" ctrllimited="true" ctrlrange="-1 1" gear="1.91" kp="2.7"/>
        <position name="middle_swing" joint="middle_swing" ctrllimited="true" ctrlrange="-1 1" gear="3.83" kp="0.68"/>
        <position name="ring_swing" joint="ring_swing" ctrllimited="true" ctrlrange="-1 1" gear="3.83" kp="0.68"/>
        <position name="little_swing" joint="little_swing" ctrllimited="true" ctrlrange="-1 1" gear="1.91" kp="2.7"/>
        <!-- 最靠近手掌的关节 -->
        <position name="index_joint_0" joint="index_joint_0" ctrllimited="true" ctrlrange="-1 1" gear="0.637" kp="500"/>
        <position name="middle_joint_0" joint="middle_joint_0" ctrllimited="true" ctrlrange="-1 1" gear="0.637" kp="500"/>
        <position name="ring_joint_0" joint="ring_joint_0" ctrllimited="true" ctrlrange="-1 1" gear="0.637" kp="500"/>
        <position name="little_joint_0" joint="little_joint_0" ctrllimited="true" ctrlrange="-1 1" gear="0.637" kp="500"/>
        <!-- 绳驱动 -->
        <position name="index_tendon" tendon="index_tendon" ctrllimited="true" ctrlrange="-1 1" kp="500"/>
        <position name="middle_tendon" tendon="middle_tendon" ctrllimited="true" ctrlrange="-1 1" kp="500"/>
        <position name="ring_tendon" tendon="ring_tendon" ctrllimited="true" ctrlrange="-1 1" kp="500"/>
        <position name="little_tendon" tendon="little_tendon" ctrllimited="true" ctrlrange="-1 1" kp="500"/>
        <!-- palm驱动 -->
        <position name="palm_slide_x" joint="palm_slide_x" ctrllimited="true" ctrlrange="-1 1" kp="900" dampratio="1"/>
        <position name="palm_slide_y" joint="palm_slide_y" ctrllimited="true" ctrlrange="-1 1" kp="900" dampratio="1"/>
        <position name="palm_slide_z" joint="palm_slide_z" ctrllimited="true" ctrlrange="-1 1" kp="900" dampratio="1"/>
        <position name="palm_rotate_x" joint="palm_rotate_x" ctrllimited="true" ctrlrange="-1 1" gear="5" kp="20" dampratio="1"/>
        <position name="palm_rotate_y" joint="palm_rotate_y" ctrllimited="true" ctrlrange="-1 1" gear="5" kp="20" dampratio="1"/>
        <position name="palm_rotate_z" joint="palm_rotate_z" ctrllimited="true" ctrlrange="-1 1" gear="0.318" kp="3000" dampratio="1"/>
    </actuator>
    <sensor>
        <!-- cube sensor -->
        <framepos name="cube_pos" objtype="body" objname="cube"/>
        <framequat name="cube_quat" objtype="body" objname="cube"/>
        <framelinvel name="cube_linvel" objtype="body" objname="cube"/>
        <frameangvel name="cube_angvel" objtype="body" objname="cube"/>
        <frameangacc name="cube_angacc" objtype="body" objname="cube"/>
        <framezaxis name="cube_upvector" objtype="body" objname="cube"/>
        <!-- palm pos sensor -->
        <framepos name="palm_pos" objtype="site" objname="inner_palm_5"/>
        <!-- fingertip pos sensor -->
        <framepos name="thumb_fingertip_pos" objtype="site" objname="thumb_tip"/>
        <framepos name="index_fingertip_pos" objtype="site" objname="index_tip"/>
        <framepos name="middle_fingertip_pos" objtype="site" objname="middle_tip"/>
        <framepos name="ring_fingertip_pos" objtype="site" objname="ring_tip"/>
        <framepos name="little_fingertip_pos" objtype="site" objname="little_tip"/>
        <!-- touch sensor -->
        <touch name="thumb_touch" site="thumb_tip"/>
        <touch name="index_touch" site="index_tip"/>
        <touch name="middle_touch" site="middle_tip"/>
        <touch name="ring_touch" site="ring_tip"/>
        <touch name="little_touch" site="little_tip"/>
    </sensor>
</mujoco>